2024-05-28 17:56:04,225 Exception on /register [POST] [in /home/mokeira/.local/lib/python3.8/site-packages/flask/app.py:828]
Traceback (most recent call last):
  File "/home/mokeira/.local/lib/python3.8/site-packages/flask/app.py", line 1463, in wsgi_app
    response = self.full_dispatch_request()
  File "/home/mokeira/.local/lib/python3.8/site-packages/flask/app.py", line 872, in full_dispatch_request
    rv = self.handle_user_exception(e)
  File "/home/mokeira/.local/lib/python3.8/site-packages/flask/app.py", line 870, in full_dispatch_request
    rv = self.dispatch_request()
  File "/home/mokeira/.local/lib/python3.8/site-packages/flask/app.py", line 855, in dispatch_request
    return self.ensure_sync(self.view_functions[rule.endpoint])(**view_args)  # type: ignore[no-any-return]
  File "/mnt/c/Users/user/Desktop/Folders/software_development/chapter_12_error_handling _assesment/app/routes.py", line 92, in register
    if form.validate_on_submit():
  File "/home/mokeira/.local/lib/python3.8/site-packages/flask_wtf/form.py", line 86, in validate_on_submit
    return self.is_submitted() and self.validate(extra_validators=extra_validators)
  File "/home/mokeira/.local/lib/python3.8/site-packages/wtforms/form.py", line 329, in validate
    return super().validate(extra)
  File "/home/mokeira/.local/lib/python3.8/site-packages/wtforms/form.py", line 146, in validate
    if not field.validate(self, extra):
  File "/home/mokeira/.local/lib/python3.8/site-packages/wtforms/fields/core.py", line 246, in validate
    stop_validation = self._run_validation_chain(form, chain)
  File "/home/mokeira/.local/lib/python3.8/site-packages/wtforms/fields/core.py", line 266, in _run_validation_chain
    validator(form, self)
  File "/mnt/c/Users/user/Desktop/Folders/software_development/chapter_12_error_handling _assesment/app/forms.py", line 39, in validate_username
    user = user.query.filter_by(email=email.data).first()
UnboundLocalError: local variable 'user' referenced before assignment
2024-05-28 17:56:04,406 Exception on /register [POST] [in /home/mokeira/.local/lib/python3.8/site-packages/flask/app.py:828]
Traceback (most recent call last):
  File "/home/mokeira/.local/lib/python3.8/site-packages/flask/app.py", line 1463, in wsgi_app
    response = self.full_dispatch_request()
  File "/home/mokeira/.local/lib/python3.8/site-packages/flask/app.py", line 872, in full_dispatch_request
    rv = self.handle_user_exception(e)
  File "/home/mokeira/.local/lib/python3.8/site-packages/flask/app.py", line 870, in full_dispatch_request
    rv = self.dispatch_request()
  File "/home/mokeira/.local/lib/python3.8/site-packages/flask/app.py", line 855, in dispatch_request
    return self.ensure_sync(self.view_functions[rule.endpoint])(**view_args)  # type: ignore[no-any-return]
  File "/mnt/c/Users/user/Desktop/Folders/software_development/chapter_12_error_handling _assesment/app/routes.py", line 92, in register
    if form.validate_on_submit():
  File "/home/mokeira/.local/lib/python3.8/site-packages/flask_wtf/form.py", line 86, in validate_on_submit
    return self.is_submitted() and self.validate(extra_validators=extra_validators)
  File "/home/mokeira/.local/lib/python3.8/site-packages/wtforms/form.py", line 329, in validate
    return super().validate(extra)
  File "/home/mokeira/.local/lib/python3.8/site-packages/wtforms/form.py", line 146, in validate
    if not field.validate(self, extra):
  File "/home/mokeira/.local/lib/python3.8/site-packages/wtforms/fields/core.py", line 246, in validate
    stop_validation = self._run_validation_chain(form, chain)
  File "/home/mokeira/.local/lib/python3.8/site-packages/wtforms/fields/core.py", line 266, in _run_validation_chain
    validator(form, self)
  File "/mnt/c/Users/user/Desktop/Folders/software_development/chapter_12_error_handling _assesment/app/forms.py", line 39, in validate_username
    user = user.query.filter_by(email=email.data).first()
UnboundLocalError: local variable 'user' referenced before assignment
2024-05-28 17:56:05,804 Exception on /register [POST] [in /home/mokeira/.local/lib/python3.8/site-packages/flask/app.py:828]
Traceback (most recent call last):
  File "/home/mokeira/.local/lib/python3.8/site-packages/flask/app.py", line 1463, in wsgi_app
    response = self.full_dispatch_request()
  File "/home/mokeira/.local/lib/python3.8/site-packages/flask/app.py", line 872, in full_dispatch_request
    rv = self.handle_user_exception(e)
  File "/home/mokeira/.local/lib/python3.8/site-packages/flask/app.py", line 870, in full_dispatch_request
    rv = self.dispatch_request()
  File "/home/mokeira/.local/lib/python3.8/site-packages/flask/app.py", line 855, in dispatch_request
    return self.ensure_sync(self.view_functions[rule.endpoint])(**view_args)  # type: ignore[no-any-return]
  File "/mnt/c/Users/user/Desktop/Folders/software_development/chapter_12_error_handling _assesment/app/routes.py", line 92, in register
    if form.validate_on_submit():
  File "/home/mokeira/.local/lib/python3.8/site-packages/flask_wtf/form.py", line 86, in validate_on_submit
    return self.is_submitted() and self.validate(extra_validators=extra_validators)
  File "/home/mokeira/.local/lib/python3.8/site-packages/wtforms/form.py", line 329, in validate
    return super().validate(extra)
  File "/home/mokeira/.local/lib/python3.8/site-packages/wtforms/form.py", line 146, in validate
    if not field.validate(self, extra):
  File "/home/mokeira/.local/lib/python3.8/site-packages/wtforms/fields/core.py", line 246, in validate
    stop_validation = self._run_validation_chain(form, chain)
  File "/home/mokeira/.local/lib/python3.8/site-packages/wtforms/fields/core.py", line 266, in _run_validation_chain
    validator(form, self)
  File "/mnt/c/Users/user/Desktop/Folders/software_development/chapter_12_error_handling _assesment/app/forms.py", line 39, in validate_username
    user = user.query.filter_by(email=email.data).first()
UnboundLocalError: local variable 'user' referenced before assignment
2024-05-28 17:58:24,908 Tinker Full-Stack App [in /mnt/c/Users/user/Desktop/Folders/software_development/chapter_12_error_handling _assesment/app/__init__.py:49]
2024-05-28 17:58:32,499 Exception on /register [GET] [in /home/mokeira/.local/lib/python3.8/site-packages/flask/app.py:828]
Traceback (most recent call last):
  File "/home/mokeira/.local/lib/python3.8/site-packages/flask/app.py", line 1463, in wsgi_app
    response = self.full_dispatch_request()
  File "/home/mokeira/.local/lib/python3.8/site-packages/flask/app.py", line 872, in full_dispatch_request
    rv = self.handle_user_exception(e)
  File "/home/mokeira/.local/lib/python3.8/site-packages/flask/app.py", line 870, in full_dispatch_request
    rv = self.dispatch_request()
  File "/home/mokeira/.local/lib/python3.8/site-packages/flask/app.py", line 855, in dispatch_request
    return self.ensure_sync(self.view_functions[rule.endpoint])(**view_args)  # type: ignore[no-any-return]
  File "/mnt/c/Users/user/Desktop/Folders/software_development/chapter_12_error_handling _assesment/app/routes.py", line 91, in register
    form= RegisterForm()
  File "/home/mokeira/.local/lib/python3.8/site-packages/wtforms/form.py", line 208, in __call__
    return type.__call__(cls, *args, **kwargs)
TypeError: __init__() missing 1 required positional argument: 'original_username'
2024-05-28 17:58:50,556 Tinker Full-Stack App [in /mnt/c/Users/user/Desktop/Folders/software_development/chapter_12_error_handling _assesment/app/__init__.py:49]
2024-05-28 18:01:45,796 Tinker Full-Stack App [in /mnt/c/Users/user/Desktop/Folders/software_development/chapter_12_error_handling _assesment/app/__init__.py:49]
2024-05-28 18:02:41,727 Exception on /register [POST] [in /home/mokeira/.local/lib/python3.8/site-packages/flask/app.py:828]
Traceback (most recent call last):
  File "/home/mokeira/.local/lib/python3.8/site-packages/flask/app.py", line 1463, in wsgi_app
    response = self.full_dispatch_request()
  File "/home/mokeira/.local/lib/python3.8/site-packages/flask/app.py", line 872, in full_dispatch_request
    rv = self.handle_user_exception(e)
  File "/home/mokeira/.local/lib/python3.8/site-packages/flask/app.py", line 870, in full_dispatch_request
    rv = self.dispatch_request()
  File "/home/mokeira/.local/lib/python3.8/site-packages/flask/app.py", line 855, in dispatch_request
    return self.ensure_sync(self.view_functions[rule.endpoint])(**view_args)  # type: ignore[no-any-return]
  File "/mnt/c/Users/user/Desktop/Folders/software_development/chapter_12_error_handling _assesment/app/routes.py", line 92, in register
    if form.validate_on_submit():
  File "/home/mokeira/.local/lib/python3.8/site-packages/flask_wtf/form.py", line 86, in validate_on_submit
    return self.is_submitted() and self.validate(extra_validators=extra_validators)
  File "/home/mokeira/.local/lib/python3.8/site-packages/wtforms/form.py", line 329, in validate
    return super().validate(extra)
  File "/home/mokeira/.local/lib/python3.8/site-packages/wtforms/form.py", line 146, in validate
    if not field.validate(self, extra):
  File "/home/mokeira/.local/lib/python3.8/site-packages/wtforms/fields/core.py", line 246, in validate
    stop_validation = self._run_validation_chain(form, chain)
  File "/home/mokeira/.local/lib/python3.8/site-packages/wtforms/fields/core.py", line 266, in _run_validation_chain
    validator(form, self)
  File "/mnt/c/Users/user/Desktop/Folders/software_development/chapter_12_error_handling _assesment/app/forms.py", line 40, in validate_username
    user = user.query.filter_by(email=email.data).first()
UnboundLocalError: local variable 'user' referenced before assignment
